Workbook
Name Engagement_Metric: Table15[[#Headers],[#Data],[Engagement Metric]]
Name Engagement_Metric: Table15[[#Headers],[#Data],[Engagement Metric]]
Name Engagement_Metric: Table15[[#Headers],[#Data],[Engagement Metric]]
Name Slicer_Campaign_Name: #N/A
Name Slicer_Platform: #N/A
Name Slicer_Platform1: #N/A

Sheet Posts
A1: Post ID | B1: Platform | C1: Date | D1: Content Type | E1: Post Text | F1: Likes | G1: Shares | H1: Comments | I1: Impressions | J1: Reach | K1: Clicks | L1: Hastag_1 | M1: Hastag_2 | N1: Campaign_Name
A2: SP001 | B2: Instagram | C2: 45781 | D2: Text | E2: Discover fresh beats on Spotify! | F2: 2414 | G2: 245 | H2: 137 | I2: 21181 | J2: 45292 | K2: 133 | L2: #SoundtrackOfLife | M2: #NowPlaying | N2: ChillVibes
A3: SP002 | B3: Instagram | C3: 45689 | D3: Text | E3: Explore the latest podcasts now. | F3: 1934 | G3: 210 | H3: 393 | I3: 29129 | J3: 73287 | K3: 273 | L3: #DiscoverWeekly | N3: IndieWave
A4: SP003 | B4: Twitter | C4: 45629 | D4: Story | E4: New music just dropped. Hit play! | F4: 3092 | G4: 177 | H4: 81 | I4: 47533 | J4: 29220 | K4: 121 | L4: #MusicForEveryone | M4: #NowPlaying | N4: ChillVibes
A5: SP004 | B5: Instagram | C5: 45629 | D5: Text | E5: Wrapped is here! Relive your top tracks | F5: 3173 | G5: 229 | H5: 197 | I5: 29604 | J5: 21809 | K5: 272 | L5: #SoundtrackOfLife | M5: #NowPlaying | N5: ChillVibes
A6: SP005 | B6: YouTube | C6: 45388 | D6: Text | E6: Music that moves you only on Spotify. | F6: 2748 | G6: 145 | H6: 315 | I6: 24401 | J6: 61182 | K6: 200 | L6: #DiscoverWeekly | M6: #SpotifyWrapped | N6: IndieWave
A7: SP006 | B7: YouTube | C7: 45456 | D7: Text | E7: Whats your vibe today? | F7: 3882 | G7: 239 | H7: 275 | I7: 58748 | J7: 44646 | K7: 149 | L7: #DiscoverWeekly | M7: #SpotifyWrapped | N7: IndieWave
A8: SP007 | B8: Twitter | C8: 45645 | D8: Story | E8: Get into the groove with our new drop! | F8: 4674 | G8: 409 | H8: 327 | I8: 20756 | J8: 63599 | K8: 212 | L8: #SoundtrackOfLife | M8: #NowPlaying | N8: ChillVibes
A9: SP008 | B9: Twitter | C9: 45421 | D9: Story | E9: Wrapped is here! Relive your top tracks | F9: 1428 | G9: 347 | H9: 67 | I9: 21148 | J9: 19712 | K9: 120 | L9: #DiscoverWeekly | M9: #MusicForEveryone | N9: ChillVibes
A10: SP009 | B10: Twitter | C10: 45823 | D10: Text | E10: Top trending tracks updated daily! | F10: 4432 | G10: 223 | H10: 299 | I10: 59016 | J10: 21742 | K10: 171 | L10: #NowPlaying | N10: ChillVibes
A11: SP010 | B11: Twitter | C11: 45630 | D11: Text | E11: Wrapped is here! Relive your top tracks | F11: 2357 | G11: 274 | H11: 172 | I11: 21566 | J11: 66829 | K11: 284 | L11: #NowPlaying | N11: ChillVibes
A12: SP011 | B12: Twitter | C12: 45357 | D12: Text | E12: Discover fresh beats on Spotify! | F12: 1971 | G12: 370 | H12: 306 | I12: 31316 | J12: 27897 | K12: 88 | L12: #SoundtrackOfLife | N12: IndieWave
A13: SP012 | B13: Instagram | C13: 45426 | D13: Text | E13: Discover fresh beats on Spotify! | F13: 1485 | G13: 353 | H13: 244 | I13: 38419 | J13: 38556 | K13: 86 | L13: #SoundtrackOfLife | M13: #NowPlaying | N13: ChillVibes
A14: SP013 | B14: Twitter | C14: 45826 | D14: Story | E14: Discover fresh beats on Spotify! | F14: 3956 | G14: 319 | H14: 61 | I14: 58162 | J14: 28720 | K14: 213 | L14: #MusicForEveryone | M14: #NowPlaying | N14: ChillVibes
A15: SP014 | B15: Twitter | C15: 45573 | D15: Text | E15: From pop to podcasts, its all here. | F15: 2460 | G15: 409 | H15: 253 | I15: 36702 | J15: 46122 | K15: 264 | L15: #NowPlaying | N15: ChillVibes
A16: SP015 | B16: Twitter | C16: 45418 | D16: Text | E16: Your weekend playlist is waiting. | F16: 3476 | G16: 355 | H16: 396 | I16: 37492 | J16: 27285 | K16: 179 | L16: #NowPlaying | N16: ChillVibes
A17: SP016 | B17: Twitter | C17: 45655 | D17: Story | E17: New music just dropped. Hit play! | F17: 4049 | G17: 377 | H17: 94 | I17: 48182 | J17: 42875 | K17: 172 | L17: #MusicForEveryone | M17: #NowPlaying | N17: ChillVibes
A18: SP017 | B18: Twitter | C18: 45453 | D18: Text | E18: Whats your vibe today? | F18: 1514 | G18: 164 | H18: 275 | I18: 41364 | J18: 44389 | K18: 83 | L18: #NowPlaying | N18: ChillVibes
A19: SP018 | B19: Instagram | C19: 45325 | D19: Story | E19: Music that moves you only on Spotify. | F19: 4281 | G19: 101 | H19: 163 | I19: 32278 | J19: 53382 | K19: 235 | L19: #NowPlaying | N19: Wrapped2024
A20: SP019 | B20: YouTube | C20: 45458 | D20: Reel | E20: Get into the groove with our new drop! | F20: 1751 | G20: 143 | H20: 151 | I20: 31826 | J20: 47729 | K20: 95 | L20: #DiscoverWeekly | M20: #SoundtrackOfLife | N20: SummerBeats
A21: SP020 | B21: Instagram | C21: 45478 | D21: Text | E21: Your weekend playlist is waiting. | F21: 3753 | G21: 411 | H21: 308 | I21: 29138 | J21: 27678 | K21: 90 | L21: #DiscoverWeekly | N21: IndieWave
A22: SP021 | B22: Instagram | C22: 45603 | D22: Story | E22: Wrapped is here! Relive your top tracks | F22: 1678 | G22: 423 | H22: 323 | I22: 55668 | J22: 37945 | K22: 230 | L22: #NowPlaying | N22: Wrapped2024
A23: SP022 | B23: Instagram | C23: 45823 | D23: Text | E23: Whats your vibe today? | F23: 4896 | G23: 466 | H23: 233 | I23: 28621 | J23: 34270 | K23: 84 | L23: #SoundtrackOfLife | M23: #NowPlaying | N23: ChillVibes
A24: SP023 | B24: YouTube | C24: 45452 | D24: Reel | E24: From pop to podcasts, its all here. | F24: 2786 | G24: 368 | H24: 208 | I24: 42000 | J24: 39967 | K24: 103 | L24: #DiscoverWeekly | M24: #SoundtrackOfLife | N24: SummerBeats
A25: SP024 | B25: Twitter | C25: 45583 | D25: Text | E25: New music just dropped. Hit play! | F25: 2607 | G25: 379 | H25: 180 | I25: 28712 | J25: 61620 | K25: 174 | L25: #SoundtrackOfLife | N25: IndieWave
A26: SP025 | B26: YouTube | C26: 45575 | D26: Reel | E26: From pop to podcasts, its all here. | F26: 4013 | G26: 320 | H26: 92 | I26: 54605 | J26: 60169 | K26: 232 | L26: #DiscoverWeekly | M26: #SoundtrackOfLife | N26: SummerBeats
A27: SP026 | B27: Twitter | C27: 45791 | D27: Story | E27: From pop to podcasts, its all here. | F27: 2707 | G27: 103 | H27: 51 | I27: 55302 | J27: 18801 | K27: 147 | L27: #DiscoverWeekly | M27: #MusicForEveryone | N27: ChillVibes
A28: SP027 | B28: Instagram | C28: 45625 | D28: Text | E28: Whats your vibe today? | F28: 2824 | G28: 425 | H28: 274 | I28: 31004 | J28: 53488 | K28: 268 | L28: #SoundtrackOfLife | M28: #NowPlaying | N28: ChillVibes
A29: SP028 | B29: YouTube | C29: 45356 | D29: Reel | E29: Explore the latest podcasts now. | F29: 3558 | G29: 314 | H29: 199 | I29: 49612 | J29: 53929 | K29: 206 | L29: #DiscoverWeekly | M29: #SoundtrackOfLife | N29: SummerBeats
A30: SP029 | B30: Twitter | C30: 45734 | D30: Story | E30: Explore the latest podcasts now. | F30: 3418 | G30: 188 | H30: 387 | I30: 57431 | J30: 36933 | K30: 202 | L30: #MusicForEveryone | M30: #NowPlaying | N30: ChillVibes
A31: SP030 | B31: Twitter | C31: 45773 | D31: Text | E31: Discover fresh beats on Spotify! | F31: 2411 | G31: 194 | H31: 168 | I31: 26665 | J31: 71699 | K31: 197 | L31: #NowPlaying | N31: ChillVibes
A32: SP031 | B32: Instagram | C32: 45658 | D32: Text | E32: New music just dropped. Hit play! | F32: 4036 | G32: 112 | H32: 382 | I32: 56284 | J32: 29440 | K32: 279 | L32: #SoundtrackOfLife | M32: #NowPlaying | N32: ChillVibes
A33: SP032 | B33: Twitter | C33: 45419 | D33: Story | E33: Explore the latest podcasts now. | F33: 2776 | G33: 307 | H33: 178 | I33: 43365 | J33: 48408 | K33: 138 | L33: #SoundtrackOfLife | M33: #NowPlaying | N33: ChillVibes
A34: SP033 | B34: Twitter | C34: 45574 | D34: Story | E34: Discover fresh beats on Spotify! | F34: 4929 | G34: 182 | H34: 95 | I34: 32181 | J34: 31084 | K34: 289 | L34: #DiscoverWeekly | M34: #MusicForEveryone | N34: ChillVibes
A35: SP034 | B35: Instagram | C35: 45666 | D35: Text | E35: New music just dropped. Hit play! | F35: 1015 | G35: 366 | H35: 308 | I35: 38127 | J35: 63790 | K35: 287 | L35: #SoundtrackOfLife | M35: #NowPlaying | N35: ChillVibes
A36: SP035 | B36: Twitter | C36: 45785 | D36: Story | E36: Your weekend playlist is waiting. | F36: 3316 | G36: 332 | H36: 268 | I36: 40095 | J36: 36913 | K36: 265 | L36: #MusicForEveryone | M36: #NowPlaying | N36: ChillVibes
A37: SP036 | B37: Instagram | C37: 45416 | D37: Text | E37: Wrapped is here! Relive your top tracks | F37: 2274 | G37: 243 | H37: 222 | I37: 43066 | J37: 59174 | K37: 80 | L37: #DiscoverWeekly | N37: IndieWave
A38: SP037 | B38: Twitter | C38: 45804 | D38: Story | E38: Explore the latest podcasts now. | F38: 4095 | G38: 385 | H38: 400 | I38: 45300 | J38: 31795 | K38: 80 | L38: #MusicForEveryone | M38: #NowPlaying | N38: ChillVibes
A39: SP038 | B39: Instagram | C39: 45545 | D39: Story | E39: New music just dropped. Hit play! | F39: 1230 | G39: 309 | H39: 207 | I39: 44629 | J39: 40699 | K39: 195 | L39: #NowPlaying | N39: Wrapped2024
A40: SP039 | B40: Instagram | C40: 45621 | D40: Text | E40: From pop to podcasts, its all here. | F40: 1341 | G40: 472 | H40: 238 | I40: 51386 | J40: 51706 | K40: 133 | L40: #DiscoverWeekly | N40: IndieWave
...

Sheet 5.1AvgTotalImpClickLikes
A1: Post ID | B1: Platform | C1: Date | D1: Content Type | E1: Post Text | F1: Likes | G1: Shares | H1: Comments | I1: Impressions | J1: Reach | K1: Clicks | L1: Hastag_1 | M1: Hastag_2 | N1: Campaign_Name
A2: SP001 | B2: Instagram | C2: 45781 | D2: Text | E2: Discover fresh beats on Spotify! | F2: 2414 | G2: 245 | H2: 137 | I2: 21181 | J2: 45292 | K2: 133 | L2: #SoundtrackOfLife | M2: #NowPlaying | N2: ChillVibes
A3: SP002 | B3: Instagram | C3: 45689 | D3: Text | E3: Explore the latest podcasts now. | F3: 1934 | G3: 210 | H3: 393 | I3: 29129 | J3: 73287 | K3: 273 | L3: #DiscoverWeekly | N3: IndieWave
A4: SP003 | B4: Twitter | C4: 45629 | D4: Story | E4: New music just dropped. Hit play! | F4: 3092 | G4: 177 | H4: 81 | I4: 47533 | J4: 29220 | K4: 121 | L4: #MusicForEveryone | M4: #NowPlaying | N4: ChillVibes | P4: Row Labels | Q4: Average of Impressions | R4: Sum of Impressions | S4: Average of Likes | T4: Sum of Likes | U4: Average of Clicks | V4: Sum of Clicks
A5: SP004 | B5: Instagram | C5: 45629 | D5: Text | E5: Wrapped is here! Relive your top tracks | F5: 3173 | G5: 229 | H5: 197 | I5: 29604 | J5: 21809 | K5: 272 | L5: #SoundtrackOfLife | M5: #NowPlaying | N5: ChillVibes | P5: ChillVibes | Q5: 41116.026 | R5: 6331868 | S5: 3058.6623 | T5: 471034 | U5: 186.41558 | V5: 28708
A6: SP005 | B6: YouTube | C6: 45388 | D6: Text | E6: Music that moves you only on Spotify. | F6: 2748 | G6: 145 | H6: 315 | I6: 24401 | J6: 61182 | K6: 200 | L6: #DiscoverWeekly | M6: #SpotifyWrapped | N6: IndieWave | P6: IndieWave | Q6: 42971.33 | R6: 4039305 | S6: 2919.734 | T6: 274455 | U6: 199.11702 | V6: 18717
A7: SP006 | B7: YouTube | C7: 45456 | D7: Text | E7: Whats your vibe today? | F7: 3882 | G7: 239 | H7: 275 | I7: 58748 | J7: 44646 | K7: 149 | L7: #DiscoverWeekly | M7: #SpotifyWrapped | N7: IndieWave | P7: SummerBeats | Q7: 42546.655 | R7: 1233853 | S7: 3099 | T7: 89871 | U7: 191.62069 | V7: 5557
A8: SP007 | B8: Twitter | C8: 45645 | D8: Story | E8: Get into the groove with our new drop! | F8: 4674 | G8: 409 | H8: 327 | I8: 20756 | J8: 63599 | K8: 212 | L8: #SoundtrackOfLife | M8: #NowPlaying | N8: ChillVibes | P8: Wrapped2024 | Q8: 37626.348 | R8: 865406 | S8: 2687.6087 | T8: 61815 | U8: 200.6087 | V8: 4614
A9: SP008 | B9: Twitter | C9: 45421 | D9: Story | E9: Wrapped is here! Relive your top tracks | F9: 1428 | G9: 347 | H9: 67 | I9: 21148 | J9: 19712 | K9: 120 | L9: #DiscoverWeekly | M9: #MusicForEveryone | N9: ChillVibes
A10: SP009 | B10: Twitter | C10: 45823 | D10: Text | E10: Top trending tracks updated daily! | F10: 4432 | G10: 223 | H10: 299 | I10: 59016 | J10: 21742 | K10: 171 | L10: #NowPlaying | N10: ChillVibes
A11: SP010 | B11: Twitter | C11: 45630 | D11: Text | E11: Wrapped is here! Relive your top tracks | F11: 2357 | G11: 274 | H11: 172 | I11: 21566 | J11: 66829 | K11: 284 | L11: #NowPlaying | N11: ChillVibes
A12: SP011 | B12: Twitter | C12: 45357 | D12: Text | E12: Discover fresh beats on Spotify! | F12: 1971 | G12: 370 | H12: 306 | I12: 31316 | J12: 27897 | K12: 88 | L12: #SoundtrackOfLife | N12: IndieWave
A13: SP012 | B13: Instagram | C13: 45426 | D13: Text | E13: Discover fresh beats on Spotify! | F13: 1485 | G13: 353 | H13: 244 | I13: 38419 | J13: 38556 | K13: 86 | L13: #SoundtrackOfLife | M13: #NowPlaying | N13: ChillVibes
A14: SP013 | B14: Twitter | C14: 45826 | D14: Story | E14: Discover fresh beats on Spotify! | F14: 3956 | G14: 319 | H14: 61 | I14: 58162 | J14: 28720 | K14: 213 | L14: #MusicForEveryone | M14: #NowPlaying | N14: ChillVibes
A15: SP014 | B15: Twitter | C15: 45573 | D15: Text | E15: From pop to podcasts, its all here. | F15: 2460 | G15: 409 | H15: 253 | I15: 36702 | J15: 46122 | K15: 264 | L15: #NowPlaying | N15: ChillVibes
A16: SP015 | B16: Twitter | C16: 45418 | D16: Text | E16: Your weekend playlist is waiting. | F16: 3476 | G16: 355 | H16: 396 | I16: 37492 | J16: 27285 | K16: 179 | L16: #NowPlaying | N16: ChillVibes
A17: SP016 | B17: Twitter | C17: 45655 | D17: Story | E17: New music just dropped. Hit play! | F17: 4049 | G17: 377 | H17: 94 | I17: 48182 | J17: 42875 | K17: 172 | L17: #MusicForEveryone | M17: #NowPlaying | N17: ChillVibes
A18: SP017 | B18: Twitter | C18: 45453 | D18: Text | E18: Whats your vibe today? | F18: 1514 | G18: 164 | H18: 275 | I18: 41364 | J18: 44389 | K18: 83 | L18: #NowPlaying | N18: ChillVibes
A19: SP018 | B19: Instagram | C19: 45325 | D19: Story | E19: Music that moves you only on Spotify. | F19: 4281 | G19: 101 | H19: 163 | I19: 32278 | J19: 53382 | K19: 235 | L19: #NowPlaying | N19: Wrapped2024
A20: SP019 | B20: YouTube | C20: 45458 | D20: Reel | E20: Get into the groove with our new drop! | F20: 1751 | G20: 143 | H20: 151 | I20: 31826 | J20: 47729 | K20: 95 | L20: #DiscoverWeekly | M20: #SoundtrackOfLife | N20: SummerBeats
A21: SP020 | B21: Instagram | C21: 45478 | D21: Text | E21: Your weekend playlist is waiting. | F21: 3753 | G21: 411 | H21: 308 | I21: 29138 | J21: 27678 | K21: 90 | L21: #DiscoverWeekly | N21: IndieWave
A22: SP021 | B22: Instagram | C22: 45603 | D22: Story | E22: Wrapped is here! Relive your top tracks | F22: 1678 | G22: 423 | H22: 323 | I22: 55668 | J22: 37945 | K22: 230 | L22: #NowPlaying | N22: Wrapped2024
A23: SP022 | B23: Instagram | C23: 45823 | D23: Text | E23: Whats your vibe today? | F23: 4896 | G23: 466 | H23: 233 | I23: 28621 | J23: 34270 | K23: 84 | L23: #SoundtrackOfLife | M23: #NowPlaying | N23: ChillVibes
A24: SP023 | B24: YouTube | C24: 45452 | D24: Reel | E24: From pop to podcasts, its all here. | F24: 2786 | G24: 368 | H24: 208 | I24: 42000 | J24: 39967 | K24: 103 | L24: #DiscoverWeekly | M24: #SoundtrackOfLife | N24: SummerBeats
A25: SP024 | B25: Twitter | C25: 45583 | D25: Text | E25: New music just dropped. Hit play! | F25: 2607 | G25: 379 | H25: 180 | I25: 28712 | J25: 61620 | K25: 174 | L25: #SoundtrackOfLife | N25: IndieWave
A26: SP025 | B26: YouTube | C26: 45575 | D26: Reel | E26: From pop to podcasts, its all here. | F26: 4013 | G26: 320 | H26: 92 | I26: 54605 | J26: 60169 | K26: 232 | L26: #DiscoverWeekly | M26: #SoundtrackOfLife | N26: SummerBeats
A27: SP026 | B27: Twitter | C27: 45791 | D27: Story | E27: From pop to podcasts, its all here. | F27: 2707 | G27: 103 | H27: 51 | I27: 55302 | J27: 18801 | K27: 147 | L27: #DiscoverWeekly | M27: #MusicForEveryone | N27: ChillVibes
A28: SP027 | B28: Instagram | C28: 45625 | D28: Text | E28: Whats your vibe today? | F28: 2824 | G28: 425 | H28: 274 | I28: 31004 | J28: 53488 | K28: 268 | L28: #SoundtrackOfLife | M28: #NowPlaying | N28: ChillVibes
A29: SP028 | B29: YouTube | C29: 45356 | D29: Reel | E29: Explore the latest podcasts now. | F29: 3558 | G29: 314 | H29: 199 | I29: 49612 | J29: 53929 | K29: 206 | L29: #DiscoverWeekly | M29: #SoundtrackOfLife | N29: SummerBeats
A30: SP029 | B30: Twitter | C30: 45734 | D30: Story | E30: Explore the latest podcasts now. | F30: 3418 | G30: 188 | H30: 387 | I30: 57431 | J30: 36933 | K30: 202 | L30: #MusicForEveryone | M30: #NowPlaying | N30: ChillVibes
A31: SP030 | B31: Twitter | C31: 45773 | D31: Text | E31: Discover fresh beats on Spotify! | F31: 2411 | G31: 194 | H31: 168 | I31: 26665 | J31: 71699 | K31: 197 | L31: #NowPlaying | N31: ChillVibes
A32: SP031 | B32: Instagram | C32: 45658 | D32: Text | E32: New music just dropped. Hit play! | F32: 4036 | G32: 112 | H32: 382 | I32: 56284 | J32: 29440 | K32: 279 | L32: #SoundtrackOfLife | M32: #NowPlaying | N32: ChillVibes
A33: SP032 | B33: Twitter | C33: 45419 | D33: Story | E33: Explore the latest podcasts now. | F33: 2776 | G33: 307 | H33: 178 | I33: 43365 | J33: 48408 | K33: 138 | L33: #SoundtrackOfLife | M33: #NowPlaying | N33: ChillVibes
A34: SP033 | B34: Twitter | C34: 45574 | D34: Story | E34: Discover fresh beats on Spotify! | F34: 4929 | G34: 182 | H34: 95 | I34: 32181 | J34: 31084 | K34: 289 | L34: #DiscoverWeekly | M34: #MusicForEveryone | N34: ChillVibes
A35: SP034 | B35: Instagram | C35: 45666 | D35: Text | E35: New music just dropped. Hit play! | F35: 1015 | G35: 366 | H35: 308 | I35: 38127 | J35: 63790 | K35: 287 | L35: #SoundtrackOfLife | M35: #NowPlaying | N35: ChillVibes
A36: SP035 | B36: Twitter | C36: 45785 | D36: Story | E36: Your weekend playlist is waiting. | F36: 3316 | G36: 332 | H36: 268 | I36: 40095 | J36: 36913 | K36: 265 | L36: #MusicForEveryone | M36: #NowPlaying | N36: ChillVibes
A37: SP036 | B37: Instagram | C37: 45416 | D37: Text | E37: Wrapped is here! Relive your top tracks | F37: 2274 | G37: 243 | H37: 222 | I37: 43066 | J37: 59174 | K37: 80 | L37: #DiscoverWeekly | N37: IndieWave
A38: SP037 | B38: Twitter | C38: 45804 | D38: Story | E38: Explore the latest podcasts now. | F38: 4095 | G38: 385 | H38: 400 | I38: 45300 | J38: 31795 | K38: 80 | L38: #MusicForEveryone | M38: #NowPlaying | N38: ChillVibes
A39: SP038 | B39: Instagram | C39: 45545 | D39: Story | E39: New music just dropped. Hit play! | F39: 1230 | G39: 309 | H39: 207 | I39: 44629 | J39: 40699 | K39: 195 | L39: #NowPlaying | N39: Wrapped2024
A40: SP039 | B40: Instagram | C40: 45621 | D40: Text | E40: From pop to podcasts, its all here. | F40: 1341 | G40: 472 | H40: 238 | I40: 51386 | J40: 51706 | K40: 133 | L40: #DiscoverWeekly | N40: IndieWave
...

Sheet 5.2EngagementMetric
A1: Post ID | B1: Platform | C1: Date | D1: Content Type | E1: Post Text | F1: Likes | G1: Shares | H1: Comments | I1: Impressions | J1: Reach | K1: Clicks | L1: Hastag_1 | M1: Hastag_2 | N1: Campaign_Name | O1: Engagement Metric
A2: SP129 | B2: Twitter | C2: 45839 | D2: Story | E2: Explore the latest podcasts now. | F2: 3219 | G2: 424 | H2: 267 | I2: 48879 | J2: 37691 | K2: 224 | L2: #DiscoverWeekly | M2: #MusicForEveryone | N2: ChillVibes | O2: =Table15[[#This Row],[Likes]]+Table15[[#This Row],[Shares]]+Table15[[#This Row],[Comments]] -> 3910
A3: SP148 | B3: Twitter | C3: 45696 | D3: Story | E3: Your weekend playlist is waiting. | F3: 4752 | G3: 334 | H3: 56 | I3: 48017 | J3: 55534 | K3: 270 | L3: #DiscoverWeekly | M3: #MusicForEveryone | N3: ChillVibes | O3: =Table15[[#This Row],[Likes]]+Table15[[#This Row],[Shares]]+Table15[[#This Row],[Comments]] -> 5142 | Q3: Column1 | R3: Caimpaign Days | S3: Total Engagement | T3: Avg Daily during Engagement | U3: Total Engagement Before | V3: Avg_Before30Days | W3: Rate_Uplift | X3: Rate_Engagement
A4: SP298 | B4: Twitter | C4: 45838 | D4: Text | E4: Whats your vibe today? | F4: 2275 | G4: 285 | H4: 125 | I4: 43970 | J4: 74761 | K4: 83 | L4: #NowPlaying | N4: ChillVibes | O4: =Table15[[#This Row],[Likes]]+Table15[[#This Row],[Shares]]+Table15[[#This Row],[Comments]] -> 2685 | Q4: ='Campaign Metadata'!A5 -> IndieWave | R4: ='Campaign Metadata'!I5 -> 31 | S4: 27073 | T4: =S4/R4 -> 873.32258 | U4: 22181 | V4: =Table6[[#This Row],[Total Engagement Before]]/30 -> 739.36667 | W4: =Table6[[#This Row],[Avg Daily during Engagement]]-Table6[[#This Row],[Avg_Before30Days]] -> 133.95591 | X4: =Table6[[#This Row],[Rate_Uplift]]/Table6[[#This Row],[Avg_Before30Days]] -> 0.18117657
A5: SP222 | B5: Twitter | C5: 45829 | D5: Text | E5: Explore the latest podcasts now. | F5: 3611 | G5: 127 | H5: 139 | I5: 44768 | J5: 29435 | K5: 178 | L5: #NowPlaying | N5: ChillVibes | O5: =Table15[[#This Row],[Likes]]+Table15[[#This Row],[Shares]]+Table15[[#This Row],[Comments]] -> 3877 | Q5: ='Campaign Metadata'!A4 -> ChillVibes | R5: ='Campaign Metadata'!I4 -> 32 | S5: 40373 | T5: =S5/R5 -> 1261.6562 | U5: 61410 | V5: =Table6[[#This Row],[Total Engagement Before]]/30 -> 2047 | W5: =Table6[[#This Row],[Avg Daily during Engagement]]-Table6[[#This Row],[Avg_Before30Days]] -> -785.34375 | X5: =Table6[[#This Row],[Rate_Uplift]]/Table6[[#This Row],[Avg_Before30Days]] -> -0.38365596
A6: SP005 | B6: YouTube | C6: 45388 | D6: Text | E6: Music that moves you only on Spotify. | F6: 2748 | G6: 145 | H6: 315 | I6: 24401 | J6: 61182 | K6: 200 | L6: #DiscoverWeekly | M6: #SpotifyWrapped | N6: IndieWave | O6: =Table15[[#This Row],[Likes]]+Table15[[#This Row],[Shares]]+Table15[[#This Row],[Comments]] -> 3208 | Q6: ='Campaign Metadata'!A2 -> SummerBeats | R6: ='Campaign Metadata'!I2 -> 31 | S6: 7338 | T6: =S6/R6 -> 236.70968 | U6: 25963 | V6: =Table6[[#This Row],[Total Engagement Before]]/30 -> 865.43333 | W6: =Table6[[#This Row],[Avg Daily during Engagement]]-Table6[[#This Row],[Avg_Before30Days]] -> -628.72366 | X6: =Table6[[#This Row],[Rate_Uplift]]/Table6[[#This Row],[Avg_Before30Days]] -> -0.72648422
A7: SP006 | B7: YouTube | C7: 45456 | D7: Text | E7: Whats your vibe today? | F7: 3882 | G7: 239 | H7: 275 | I7: 58748 | J7: 44646 | K7: 149 | L7: #DiscoverWeekly | M7: #SpotifyWrapped | N7: IndieWave | O7: =Table15[[#This Row],[Likes]]+Table15[[#This Row],[Shares]]+Table15[[#This Row],[Comments]] -> 4396 | Q7: ='Campaign Metadata'!A3 -> Wrapped2024 | R7: ='Campaign Metadata'!I3 -> 31 | S7: 9546 | T7: =S7/R7 -> 307.93548 | U7: 53787 | V7: =Table6[[#This Row],[Total Engagement Before]]/30 -> 1792.9 | W7: =Table6[[#This Row],[Avg Daily during Engagement]]-Table6[[#This Row],[Avg_Before30Days]] -> -1484.9645 | X7: =Table6[[#This Row],[Rate_Uplift]]/Table6[[#This Row],[Avg_Before30Days]] -> -0.82824726
A8: SP212 | B8: Twitter | C8: 45827 | D8: Story | E8: Whats your vibe today? | F8: 1433 | G8: 452 | H8: 305 | I8: 54541 | J8: 63700 | K8: 296 | L8: #DiscoverWeekly | M8: #MusicForEveryone | N8: ChillVibes | O8: =Table15[[#This Row],[Likes]]+Table15[[#This Row],[Shares]]+Table15[[#This Row],[Comments]] -> 2190
A9: SP013 | B9: Twitter | C9: 45826 | D9: Story | E9: Discover fresh beats on Spotify! | F9: 3956 | G9: 319 | H9: 61 | I9: 58162 | J9: 28720 | K9: 213 | L9: #MusicForEveryone | M9: #NowPlaying | N9: ChillVibes | O9: =Table15[[#This Row],[Likes]]+Table15[[#This Row],[Shares]]+Table15[[#This Row],[Comments]] -> 4336
A10: SP080 | B10: Instagram | C10: 45825 | D10: Text | E10: Music that moves you only on Spotify. | F10: 2284 | G10: 187 | H10: 260 | I10: 37400 | J10: 65014 | K10: 157 | L10: #SoundtrackOfLife | M10: #NowPlaying | N10: ChillVibes | O10: =Table15[[#This Row],[Likes]]+Table15[[#This Row],[Shares]]+Table15[[#This Row],[Comments]] -> 2731
A11: SP265 | B11: Twitter | C11: 45825 | D11: Story | E11: Explore the latest podcasts now. | F11: 4341 | G11: 141 | H11: 63 | I11: 50081 | J11: 27507 | K11: 221 | L11: #DiscoverWeekly | M11: #MusicForEveryone | N11: ChillVibes | O11: =Table15[[#This Row],[Likes]]+Table15[[#This Row],[Shares]]+Table15[[#This Row],[Comments]] -> 4545
A12: SP011 | B12: Twitter | C12: 45357 | D12: Text | E12: Discover fresh beats on Spotify! | F12: 1971 | G12: 370 | H12: 306 | I12: 31316 | J12: 27897 | K12: 88 | L12: #SoundtrackOfLife | N12: IndieWave | O12: =Table15[[#This Row],[Likes]]+Table15[[#This Row],[Shares]]+Table15[[#This Row],[Comments]] -> 2647
A13: SP009 | B13: Twitter | C13: 45823 | D13: Text | E13: Top trending tracks updated daily! | F13: 4432 | G13: 223 | H13: 299 | I13: 59016 | J13: 21742 | K13: 171 | L13: #NowPlaying | N13: ChillVibes | O13: =Table15[[#This Row],[Likes]]+Table15[[#This Row],[Shares]]+Table15[[#This Row],[Comments]] -> 4954
A14: SP022 | B14: Instagram | C14: 45823 | D14: Text | E14: Whats your vibe today? | F14: 4896 | G14: 466 | H14: 233 | I14: 28621 | J14: 34270 | K14: 84 | L14: #SoundtrackOfLife | M14: #NowPlaying | N14: ChillVibes | O14: =Table15[[#This Row],[Likes]]+Table15[[#This Row],[Shares]]+Table15[[#This Row],[Comments]] -> 5595
A15: SP238 | B15: Instagram | C15: 45823 | D15: Text | E15: Explore the latest podcasts now. | F15: 2478 | G15: 427 | H15: 242 | I15: 59272 | J15: 37833 | K15: 214 | L15: #SoundtrackOfLife | M15: #NowPlaying | N15: ChillVibes | O15: =Table15[[#This Row],[Likes]]+Table15[[#This Row],[Shares]]+Table15[[#This Row],[Comments]] -> 3147
A16: SP153 | B16: Twitter | C16: 45819 | D16: Story | E16: Explore the latest podcasts now. | F16: 3805 | G16: 453 | H16: 63 | I16: 52395 | J16: 72934 | K16: 87 | L16: #DiscoverWeekly | M16: #MusicForEveryone | N16: ChillVibes | O16: =Table15[[#This Row],[Likes]]+Table15[[#This Row],[Shares]]+Table15[[#This Row],[Comments]] -> 4321
A17: SP040 | B17: Twitter | C17: 45818 | D17: Text | E17: Explore the latest podcasts now. | F17: 3615 | G17: 192 | H17: 162 | I17: 27492 | J17: 35341 | K17: 125 | L17: #NowPlaying | N17: ChillVibes | O17: =Table15[[#This Row],[Likes]]+Table15[[#This Row],[Shares]]+Table15[[#This Row],[Comments]] -> 3969
A18: SP217 | B18: Instagram | C18: 45808 | D18: Text | E18: Whats your vibe today? | F18: 2169 | G18: 240 | H18: 57 | I18: 26109 | J18: 46667 | K18: 133 | L18: #SoundtrackOfLife | M18: #NowPlaying | N18: ChillVibes | O18: =Table15[[#This Row],[Likes]]+Table15[[#This Row],[Shares]]+Table15[[#This Row],[Comments]] -> 2466
A19: SP018 | B19: Instagram | C19: 45325 | D19: Story | E19: Music that moves you only on Spotify. | F19: 4281 | G19: 101 | H19: 163 | I19: 32278 | J19: 53382 | K19: 235 | L19: #NowPlaying | N19: Wrapped2024 | O19: =Table15[[#This Row],[Likes]]+Table15[[#This Row],[Shares]]+Table15[[#This Row],[Comments]] -> 4545
A20: SP019 | B20: YouTube | C20: 45458 | D20: Reel | E20: Get into the groove with our new drop! | F20: 1751 | G20: 143 | H20: 151 | I20: 31826 | J20: 47729 | K20: 95 | L20: #DiscoverWeekly | M20: #SoundtrackOfLife | N20: SummerBeats | O20: =Table15[[#This Row],[Likes]]+Table15[[#This Row],[Shares]]+Table15[[#This Row],[Comments]] -> 2045
A21: SP020 | B21: Instagram | C21: 45478 | D21: Text | E21: Your weekend playlist is waiting. | F21: 3753 | G21: 411 | H21: 308 | I21: 29138 | J21: 27678 | K21: 90 | L21: #DiscoverWeekly | N21: IndieWave | O21: =Table15[[#This Row],[Likes]]+Table15[[#This Row],[Shares]]+Table15[[#This Row],[Comments]] -> 4472
A22: SP021 | B22: Instagram | C22: 45603 | D22: Story | E22: Wrapped is here! Relive your top tracks | F22: 1678 | G22: 423 | H22: 323 | I22: 55668 | J22: 37945 | K22: 230 | L22: #NowPlaying | N22: Wrapped2024 | O22: =Table15[[#This Row],[Likes]]+Table15[[#This Row],[Shares]]+Table15[[#This Row],[Comments]] -> 2424
A23: SP119 | B23: Twitter | C23: 45806 | D23: Story | E23: Music that moves you only on Spotify. | F23: 2134 | G23: 322 | H23: 114 | I23: 44338 | J23: 52165 | K23: 176 | L23: #MusicForEveryone | M23: #NowPlaying | N23: ChillVibes | O23: =Table15[[#This Row],[Likes]]+Table15[[#This Row],[Shares]]+Table15[[#This Row],[Comments]] -> 2570
A24: SP023 | B24: YouTube | C24: 45452 | D24: Reel | E24: From pop to podcasts, its all here. | F24: 2786 | G24: 368 | H24: 208 | I24: 42000 | J24: 39967 | K24: 103 | L24: #DiscoverWeekly | M24: #SoundtrackOfLife | N24: SummerBeats | O24: =Table15[[#This Row],[Likes]]+Table15[[#This Row],[Shares]]+Table15[[#This Row],[Comments]] -> 3362
A25: SP024 | B25: Twitter | C25: 45583 | D25: Text | E25: New music just dropped. Hit play! | F25: 2607 | G25: 379 | H25: 180 | I25: 28712 | J25: 61620 | K25: 174 | L25: #SoundtrackOfLife | N25: IndieWave | O25: =Table15[[#This Row],[Likes]]+Table15[[#This Row],[Shares]]+Table15[[#This Row],[Comments]] -> 3166
A26: SP025 | B26: YouTube | C26: 45575 | D26: Reel | E26: From pop to podcasts, its all here. | F26: 4013 | G26: 320 | H26: 92 | I26: 54605 | J26: 60169 | K26: 232 | L26: #DiscoverWeekly | M26: #SoundtrackOfLife | N26: SummerBeats | O26: =Table15[[#This Row],[Likes]]+Table15[[#This Row],[Shares]]+Table15[[#This Row],[Comments]] -> 4425
A27: SP077 | B27: Twitter | C27: 45805 | D27: Text | E27: From pop to podcasts, its all here. | F27: 2418 | G27: 161 | H27: 360 | I27: 30589 | J27: 41383 | K27: 88 | L27: #NowPlaying | N27: ChillVibes | O27: =Table15[[#This Row],[Likes]]+Table15[[#This Row],[Shares]]+Table15[[#This Row],[Comments]] -> 2939
A28: SP145 | B28: Twitter | C28: 45805 | D28: Story | E28: Top trending tracks updated daily! | F28: 4287 | G28: 273 | H28: 122 | I28: 40792 | J28: 23878 | K28: 277 | L28: #MusicForEveryone | M28: #NowPlaying | N28: ChillVibes | O28: =Table15[[#This Row],[Likes]]+Table15[[#This Row],[Shares]]+Table15[[#This Row],[Comments]] -> 4682
A29: SP028 | B29: YouTube | C29: 45356 | D29: Reel | E29: Explore the latest podcasts now. | F29: 3558 | G29: 314 | H29: 199 | I29: 49612 | J29: 53929 | K29: 206 | L29: #DiscoverWeekly | M29: #SoundtrackOfLife | N29: SummerBeats | O29: =Table15[[#This Row],[Likes]]+Table15[[#This Row],[Shares]]+Table15[[#This Row],[Comments]] -> 4071
A30: SP037 | B30: Twitter | C30: 45804 | D30: Story | E30: Explore the latest podcasts now. | F30: 4095 | G30: 385 | H30: 400 | I30: 45300 | J30: 31795 | K30: 80 | L30: #MusicForEveryone | M30: #NowPlaying | N30: ChillVibes | O30: =Table15[[#This Row],[Likes]]+Table15[[#This Row],[Shares]]+Table15[[#This Row],[Comments]] -> 4880
A31: SP134 | B31: Twitter | C31: 45792 | D31: Text | E31: New music just dropped. Hit play! | F31: 1583 | G31: 433 | H31: 249 | I31: 30256 | J31: 47066 | K31: 196 | L31: #NowPlaying | N31: ChillVibes | O31: =Table15[[#This Row],[Likes]]+Table15[[#This Row],[Shares]]+Table15[[#This Row],[Comments]] -> 2265
A32: SP250 | B32: Twitter | C32: 45792 | D32: Text | E32: Your weekend playlist is waiting. | F32: 4782 | G32: 210 | H32: 311 | I32: 29793 | J32: 37543 | K32: 145 | L32: #NowPlaying | N32: ChillVibes | O32: =Table15[[#This Row],[Likes]]+Table15[[#This Row],[Shares]]+Table15[[#This Row],[Comments]] -> 5303
A33: SP026 | B33: Twitter | C33: 45791 | D33: Story | E33: From pop to podcasts, its all here. | F33: 2707 | G33: 103 | H33: 51 | I33: 55302 | J33: 18801 | K33: 147 | L33: #DiscoverWeekly | M33: #MusicForEveryone | N33: ChillVibes | O33: =Table15[[#This Row],[Likes]]+Table15[[#This Row],[Shares]]+Table15[[#This Row],[Comments]] -> 2861
A34: SP086 | B34: Twitter | C34: 45791 | D34: Story | E34: Wrapped is here! Relive your top tracks | F34: 1371 | G34: 139 | H34: 96 | I34: 36140 | J34: 39395 | K34: 169 | L34: #SoundtrackOfLife | M34: #NowPlaying | N34: ChillVibes | O34: =Table15[[#This Row],[Likes]]+Table15[[#This Row],[Shares]]+Table15[[#This Row],[Comments]] -> 1606
A35: SP221 | B35: Twitter | C35: 45786 | D35: Story | E35: Music that moves you only on Spotify. | F35: 2778 | G35: 241 | H35: 317 | I35: 26247 | J35: 20677 | K35: 282 | L35: #MusicForEveryone | M35: #NowPlaying | N35: ChillVibes | O35: =Table15[[#This Row],[Likes]]+Table15[[#This Row],[Shares]]+Table15[[#This Row],[Comments]] -> 3336
A36: SP035 | B36: Twitter | C36: 45785 | D36: Story | E36: Your weekend playlist is waiting. | F36: 3316 | G36: 332 | H36: 268 | I36: 40095 | J36: 36913 | K36: 265 | L36: #MusicForEveryone | M36: #NowPlaying | N36: ChillVibes | O36: =Table15[[#This Row],[Likes]]+Table15[[#This Row],[Shares]]+Table15[[#This Row],[Comments]] -> 3916
A37: SP036 | B37: Instagram | C37: 45416 | D37: Text | E37: Wrapped is here! Relive your top tracks | F37: 2274 | G37: 243 | H37: 222 | I37: 43066 | J37: 59174 | K37: 80 | L37: #DiscoverWeekly | N37: IndieWave | O37: =Table15[[#This Row],[Likes]]+Table15[[#This Row],[Shares]]+Table15[[#This Row],[Comments]] -> 2739
A38: SP001 | B38: Instagram | C38: 45781 | D38: Text | E38: Discover fresh beats on Spotify! | F38: 2414 | G38: 245 | H38: 137 | I38: 21181 | J38: 45292 | K38: 133 | L38: #SoundtrackOfLife | M38: #NowPlaying | N38: ChillVibes | O38: =Table15[[#This Row],[Likes]]+Table15[[#This Row],[Shares]]+Table15[[#This Row],[Comments]] -> 2796
A39: SP038 | B39: Instagram | C39: 45545 | D39: Story | E39: New music just dropped. Hit play! | F39: 1230 | G39: 309 | H39: 207 | I39: 44629 | J39: 40699 | K39: 195 | L39: #NowPlaying | N39: Wrapped2024 | O39: =Table15[[#This Row],[Likes]]+Table15[[#This Row],[Shares]]+Table15[[#This Row],[Comments]] -> 1746
A40: SP039 | B40: Instagram | C40: 45621 | D40: Text | E40: From pop to podcasts, its all here. | F40: 1341 | G40: 472 | H40: 238 | I40: 51386 | J40: 51706 | K40: 133 | L40: #DiscoverWeekly | N40: IndieWave | O40: =Table15[[#This Row],[Likes]]+Table15[[#This Row],[Shares]]+Table15[[#This Row],[Comments]] -> 2051
...

Sheet Engagement Summary
A1: Week_Start_Date | B1: Platform | C1: New_Followers | D1: Unfollows | E1: Total_Followers | F1: Engagement_Rate | G1: Ad_Spend
A2: 45446 | B2: Instagram | C2: 1402 | D2: 68 | E2: 124562 | F2: 9.92 | G2: 23125
A3: 45446 | B3: Twitter | C3: 995 | D3: 86 | E3: 227958 | F3: 8.05 | G3: 22788
A4: 45446 | B4: YouTube | C4: 1472 | D4: 296 | E4: 370242 | F4: 7.72 | G4: 7810
A5: 45453 | B5: Instagram | C5: 1018 | D5: 90 | E5: 92474 | F5: 9.4 | G5: 11966
A6: 45453 | B6: Twitter | C6: 1461 | D6: 64 | E6: 328902 | F6: 9.02 | G6: 26298
A7: 45453 | B7: YouTube | C7: 545 | D7: 93 | E7: 391621 | F7: 9.96 | G7: 22029
A8: 45460 | B8: Instagram | C8: 881 | D8: 291 | E8: 95885 | F8: 5.29 | G8: 12391
A9: 45460 | B9: Twitter | C9: 1414 | D9: 131 | E9: 245947 | F9: 8.3 | G9: 14477
A10: 45460 | B10: YouTube | C10: 1472 | D10: 170 | E10: 250428 | F10: 4.66 | G10: 25040
A11: 45467 | B11: Instagram | C11: 809 | D11: 197 | E11: 87186 | F11: 9.48 | G11: 22619
A12: 45467 | B12: Twitter | C12: 1371 | D12: 250 | E12: 128620 | F12: 7.11 | G12: 12399
A13: 45467 | B13: YouTube | C13: 844 | D13: 144 | E13: 126015 | F13: 9.65 | G13: 22456
... A201: 45908 | B201: Twitter | C201: 860 | D201: 244 | E201: 348686 | F201: 5.12 | G201: 11418

Sheet 5.3CaimpaignHighestROI
A1: Week_Start_Date | B1: Platform | C1: New_Followers | D1: Unfollows | E1: Total_Followers | F1: Engagement_Rate | G1: Ad_Spend | H1: Engagement Rate
A2: 45446 | B2: Instagram | C2: 1402 | D2: 68 | E2: 124562 | F2: 9.92 | G2: 23125 | H2: =(tbl_summary[[#This Row],[Engagement_Rate]]/100)*tbl_summary[[#This Row],[Total_Followers]] -> 12356.55
A3: 45446 | B3: Twitter | C3: 995 | D3: 86 | E3: 227958 | F3: 8.05 | G3: 22788 | H3: =(tbl_summary[[#This Row],[Engagement_Rate]]/100)*tbl_summary[[#This Row],[Total_Followers]] -> 18350.619 | K3: Caimpaign | L3: Start Date | M3: End Date | N3: Platform | O3: Total Engagement | P3: Total ad spend | Q3: ROI
A4: 45446 | B4: YouTube | C4: 1472 | D4: 296 | E4: 370242 | F4: 7.72 | G4: 7810 | H4: =(tbl_summary[[#This Row],[Engagement_Rate]]/100)*tbl_summary[[#This Row],[Total_Followers]] -> 28582.682 | K4: ChillVibes | L4: 45667 | M4: 45698 | N4: Instagram,Twitter | O4: =SUMIFS(tbl_summary[Engagement Rate],tbl_summary[Week_Start_Date],">="&$L4,tbl_summary[Week_Start_Date],"<=" & $M4,tbl_summary[Platform],"Instagram")+SUMIFS(tbl_summary[Engagement Rate],tbl_summary[Week_Start_Date],">=" &$L4,tbl_summary[Week_Start_Date],"<=" & $M4,tbl_summary[Platform],"Twitter") -> 178421.35 | P4: =SUMIFS(tbl_summary[Ad_Spend],tbl_summary[Week_Start_Date],">="&$L4,tbl_summary[Week_Start_Date],"<=" & $M4,tbl_summary[Platform],"Twitter")+SUMIFS(tbl_summary[Ad_Spend],tbl_summary[Week_Start_Date],">=" &$L4,tbl_summary[Week_Start_Date],"<=" & $M4,tbl_summary[Platform],"YouTube") -> 133793 | Q4: =Table9[[#This Row],[Total Engagement]]/Table9[[#This Row],[Total ad spend]] -> 1.3335627
A5: 45453 | B5: Instagram | C5: 1018 | D5: 90 | E5: 92474 | F5: 9.4 | G5: 11966 | H5: =(tbl_summary[[#This Row],[Engagement_Rate]]/100)*tbl_summary[[#This Row],[Total_Followers]] -> 8692.556 | K5: Wrapped2024 | L5: 45627 | M5: 45657 | N5: Twitter,YouTube | O5: =SUMIFS(tbl_summary[Engagement Rate],tbl_summary[Week_Start_Date],">="&$L$5,tbl_summary[Week_Start_Date],"<=" & $M$5,tbl_summary[Platform],"Twitter")+SUMIFS(tbl_summary[Engagement Rate],tbl_summary[Week_Start_Date],">=" &$L$5,tbl_summary[Week_Start_Date],"<=" & $M$5,tbl_summary[Platform],"YouTube") -> 129797.13 | P5: =SUMIFS(tbl_summary[Ad_Spend],tbl_summary[Week_Start_Date],">="&$L5,tbl_summary[Week_Start_Date],"<=" & $M5,tbl_summary[Platform],"Twitter")+SUMIFS(tbl_summary[Ad_Spend],tbl_summary[Week_Start_Date],">=" &$L5,tbl_summary[Week_Start_Date],"<=" & $M5,tbl_summary[Platform],"YouTube") -> 143172 | Q5: =Table9[[#This Row],[Total Engagement]]/Table9[[#This Row],[Total ad spend]] -> 0.90658179
A6: 45453 | B6: Twitter | C6: 1461 | D6: 64 | E6: 328902 | F6: 9.02 | G6: 26298 | H6: =(tbl_summary[[#This Row],[Engagement_Rate]]/100)*tbl_summary[[#This Row],[Total_Followers]] -> 29666.96 | K6: SummerBeats | L6: 45458 | M6: 45488 | N6: Instagram,YouTube | O6: =SUMIFS(tbl_summary[Engagement Rate],tbl_summary[Week_Start_Date],">="&$L6,tbl_summary[Week_Start_Date],"<=" & $M6,tbl_summary[Platform],"Twitter")+SUMIFS(tbl_summary[Engagement Rate],tbl_summary[Week_Start_Date],">=" &$L6,tbl_summary[Week_Start_Date],"<=" & $M6,tbl_summary[Platform],"YouTube") -> 138182.01 | P6: =SUMIFS(tbl_summary[Ad_Spend],tbl_summary[Week_Start_Date],">="&$L6,tbl_summary[Week_Start_Date],"<=" & $M6,tbl_summary[Platform],"Twitter")+SUMIFS(tbl_summary[Ad_Spend],tbl_summary[Week_Start_Date],">=" &$L6,tbl_summary[Week_Start_Date],"<=" & $M6,tbl_summary[Platform],"YouTube") -> 174329 | Q6: =Table9[[#This Row],[Total Engagement]]/Table9[[#This Row],[Total ad spend]] -> 0.79265075
A7: 45453 | B7: YouTube | C7: 545 | D7: 93 | E7: 391621 | F7: 9.96 | G7: 22029 | H7: =(tbl_summary[[#This Row],[Engagement_Rate]]/100)*tbl_summary[[#This Row],[Total_Followers]] -> 39005.452 | K7: IndieWave | L7: 45717 | M7: 45747 | N7: Facebook,Instagram | O7: =SUMIFS(tbl_summary[Engagement Rate],tbl_summary[Week_Start_Date],">="&$L7,tbl_summary[Week_Start_Date],"<=" & $M7,tbl_summary[Platform],"Facebook")+SUMIFS(tbl_summary[Engagement Rate],tbl_summary[Week_Start_Date],">=" &$L7,tbl_summary[Week_Start_Date],"<=" & $M7,tbl_summary[Platform],"Instagram") -> 60090.679 | P7: =SUMIFS(tbl_summary[Ad_Spend],tbl_summary[Week_Start_Date],">="&$L7,tbl_summary[Week_Start_Date],"<=" & $M7,tbl_summary[Platform],"Twitter")+SUMIFS(tbl_summary[Ad_Spend],tbl_summary[Week_Start_Date],">=" &$L7,tbl_summary[Week_Start_Date],"<=" & $M7,tbl_summary[Platform],"YouTube") -> 172589 | Q7: =Table9[[#This Row],[Total Engagement]]/Table9[[#This Row],[Total ad spend]] -> 0.34817212
A8: 45460 | B8: Instagram | C8: 881 | D8: 291 | E8: 95885 | F8: 5.29 | G8: 12391 | H8: =(tbl_summary[[#This Row],[Engagement_Rate]]/100)*tbl_summary[[#This Row],[Total_Followers]] -> 5072.3165
A9: 45460 | B9: Twitter | C9: 1414 | D9: 131 | E9: 245947 | F9: 8.3 | G9: 14477 | H9: =(tbl_summary[[#This Row],[Engagement_Rate]]/100)*tbl_summary[[#This Row],[Total_Followers]] -> 20413.601
A10: 45460 | B10: YouTube | C10: 1472 | D10: 170 | E10: 250428 | F10: 4.66 | G10: 25040 | H10: =(tbl_summary[[#This Row],[Engagement_Rate]]/100)*tbl_summary[[#This Row],[Total_Followers]] -> 11669.945
A11: 45467 | B11: Instagram | C11: 809 | D11: 197 | E11: 87186 | F11: 9.48 | G11: 22619 | H11: =(tbl_summary[[#This Row],[Engagement_Rate]]/100)*tbl_summary[[#This Row],[Total_Followers]] -> 8265.2328
A12: 45467 | B12: Twitter | C12: 1371 | D12: 250 | E12: 128620 | F12: 7.11 | G12: 12399 | H12: =(tbl_summary[[#This Row],[Engagement_Rate]]/100)*tbl_summary[[#This Row],[Total_Followers]] -> 9144.882
A13: 45467 | B13: YouTube | C13: 844 | D13: 144 | E13: 126015 | F13: 9.65 | G13: 22456 | H13: =(tbl_summary[[#This Row],[Engagement_Rate]]/100)*tbl_summary[[#This Row],[Total_Followers]] -> 12160.448
A14: 45474 | B14: Instagram | C14: 786 | D14: 72 | E14: 178615 | F14: 5.43 | G14: 19328 | H14: =(tbl_summary[[#This Row],[Engagement_Rate]]/100)*tbl_summary[[#This Row],[Total_Followers]] -> 9698.7945
A15: 45474 | B15: Twitter | C15: 845 | D15: 250 | E15: 218228 | F15: 4.52 | G15: 21107 | H15: =(tbl_summary[[#This Row],[Engagement_Rate]]/100)*tbl_summary[[#This Row],[Total_Followers]] -> 9863.9056
A16: 45474 | B16: YouTube | C16: 1218 | D16: 101 | E16: 300397 | F16: 4.33 | G16: 12277 | H16: =(tbl_summary[[#This Row],[Engagement_Rate]]/100)*tbl_summary[[#This Row],[Total_Followers]] -> 13007.19
A17: 45481 | B17: Instagram | C17: 797 | D17: 130 | E17: 340121 | F17: 8.52 | G17: 11684 | H17: =(tbl_summary[[#This Row],[Engagement_Rate]]/100)*tbl_summary[[#This Row],[Total_Followers]] -> 28978.309
A18: 45481 | B18: Twitter | C18: 1471 | D18: 100 | E18: 76866 | F18: 8.55 | G18: 14412 | H18: =(tbl_summary[[#This Row],[Engagement_Rate]]/100)*tbl_summary[[#This Row],[Total_Followers]] -> 6572.043
A19: 45481 | B19: YouTube | C19: 1253 | D19: 136 | E19: 193131 | F19: 7.99 | G19: 15924 | H19: =(tbl_summary[[#This Row],[Engagement_Rate]]/100)*tbl_summary[[#This Row],[Total_Followers]] -> 15431.167
... A201: 45908 | B201: Twitter | C201: 860 | D201: 244 | E201: 348686 | F201: 5.12 | G201: 11418 | H201: =(tbl_summary[[#This Row],[Engagement_Rate]]/100)*tbl_summary[[#This Row],[Total_Followers]] -> 17852.723

Sheet 5.4FollowerGrowth
A1: Week_Start_Date | B1: Platform | C1: New_Followers | D1: Unfollows | E1: Total_Followers | F1: Engagement_Rate | G1: Ad_Spend | H1: Campaign_Name | I1: Start_Date | J1: End_Date | K1: Target_Platforms | L1: TotalNew_Follower | M1: Total_Clicks(App Download)
A2: 45446 | B2: Instagram | C2: 1402 | D2: 68 | E2: 124562 | F2: 9.92 | G2: 23125 | H2: SummerBeats | I2: 2024-06-15 | J2: 2024-07-15 | K2: Instagram,YouTube | L2: 9657 | M2: =SUMIF(Table1[Campaign_Name],"SummerBeats",Table1[Clicks]) -> 5557
A3: 45446 | B3: Twitter | C3: 995 | D3: 86 | E3: 227958 | F3: 8.05 | G3: 22788 | H3: Wrapped2024 | I3: 2024-12-01 | J3: 2024-12-31 | K3: Twitter,YouTube | L3: 9446 | M3: =SUMIF(Table1[Campaign_Name],"Wrapped2024",Table1[Clicks]) -> 4614
A4: 45446 | B4: YouTube | C4: 1472 | D4: 296 | E4: 370242 | F4: 7.72 | G4: 7810 | H4: ChillVibes | I4: 2025-01-10 | J4: 2025-02-10 | K4: Instagram,Twitter | L4: 8915 | M4: =SUMIF(Table1[Campaign_Name],"ChillVibes",Table1[Clicks]) -> 28708
A5: 45453 | B5: Instagram | C5: 1018 | D5: 90 | E5: 92474 | F5: 9.4 | G5: 11966 | H5: IndieWave | I5: 2025-03-01 | J5: 2025-03-31 | K5: Facebook,Instagram | L5: 4177 | M5: =SUMIF(Table1[Campaign_Name],"IndieWave",Table1[Clicks]) -> 18717
A6: 45453 | B6: Twitter | C6: 1461 | D6: 64 | E6: 328902 | F6: 9.02 | G6: 26298
A7: 45453 | B7: YouTube | C7: 545 | D7: 93 | E7: 391621 | F7: 9.96 | G7: 22029
A8: 45460 | B8: Instagram | C8: 881 | D8: 291 | E8: 95885 | F8: 5.29 | G8: 12391
A9: 45460 | B9: Twitter | C9: 1414 | D9: 131 | E9: 245947 | F9: 8.3 | G9: 14477
A10: 45460 | B10: YouTube | C10: 1472 | D10: 170 | E10: 250428 | F10: 4.66 | G10: 25040
A11: 45467 | B11: Instagram | C11: 809 | D11: 197 | E11: 87186 | F11: 9.48 | G11: 22619
A12: 45467 | B12: Twitter | C12: 1371 | D12: 250 | E12: 128620 | F12: 7.11 | G12: 12399
A13: 45467 | B13: YouTube | C13: 844 | D13: 144 | E13: 126015 | F13: 9.65 | G13: 22456
A14: 45474 | B14: Instagram | C14: 786 | D14: 72 | E14: 178615 | F14: 5.43 | G14: 19328
A15: 45474 | B15: Twitter | C15: 845 | D15: 250 | E15: 218228 | F15: 4.52 | G15: 21107
A16: 45474 | B16: YouTube | C16: 1218 | D16: 101 | E16: 300397 | F16: 4.33 | G16: 12277
A17: 45481 | B17: Instagram | C17: 797 | D17: 130 | E17: 340121 | F17: 8.52 | G17: 11684
... A201: 45908 | B201: Twitter | C201: 860 | D201: 244 | E201: 348686 | F201: 5.12 | G201: 11418
C205: Used Subtotal

Sheet Campaign Metadata
A1: Campaign_Name | B1: Start_Date | C1: End_Date | D1: Objective | E1: Total_Budget | F1: Target_Platforms | G1: Hastag_1 | H1: Hastag_2 | I1: Number of days
A2: SummerBeats | B2: 2024-06-15 | C2: 2024-07-15 | D2: Brand Awareness | E2: 175000 | F2: Instagram,YouTube | G2: #SpotifyWrapped | H2: #MusicForEveryone | I2: =Table5[[#This Row],[End_Date]]-Table5[[#This Row],[Start_Date]]+1 -> 31
A3: Wrapped2024 | B3: 2024-12-01 | C3: 2024-12-31 | D3: Engagement | E3: 225000 | F3: Twitter,YouTube | G3: #SpotifyWrapped | H3: #NowPlaying | I3: =Table5[[#This Row],[End_Date]]-Table5[[#This Row],[Start_Date]]+1 -> 31
A4: ChillVibes | B4: 2025-01-10 | C4: 2025-02-10 | D4: Product Launch | E4: 200000 | F4: Instagram,Twitter | G4: #ChillVibes | H4: #SoundtrackOfLife | I4: =Table5[[#This Row],[End_Date]]-Table5[[#This Row],[Start_Date]]+1 -> 32
A5: IndieWave | B5: 2025-03-01 | C5: 2025-03-31 | D5: Traffic | E5: 160000 | F5: Facebook,Instagram | G5: #DiscoverWeekly | H5: #IndieWave | I5: =Table5[[#This Row],[End_Date]]-Table5[[#This Row],[Start_Date]]+1 -> 31
